import { describe, it, expect, vi } from 'vitest'

describe('TRPC Error Handler Middleware', () => {
  it('should handle TRPC errors properly', () => {
    // Mock error handler behavior
    const mockErrorHandler = vi.fn((error) => {
      if (error.data?.code === 'BAD_REQUEST') {
        return { message: 'Validation Error', handled: true }
      }
      if (error.data?.code === 'UNAUTHORIZED') {
        return { message: 'Authentication Required', handled: true }
      }
      if (error.data?.code === 'NOT_FOUND') {
        return { message: 'Not Found', handled: true }
      }
      return { message: 'Unknown Error', handled: false }
    })

    // Test various error codes
    const badRequestError = {
      message: 'Invalid input',
      data: { code: 'BAD_REQUEST', httpStatus: 400 }
    }

    const unauthorizedError = {
      message: 'No token provided',
      data: { code: 'UNAUTHORIZED', httpStatus: 401 }
    }

    const notFoundError = {
      message: 'Resource not found',
      data: { code: 'NOT_FOUND', httpStatus: 404 }
    }

    // Test handling
    const result1 = mockErrorHandler(badRequestError)
    expect(result1.message).toBe('Validation Error')
    expect(result1.handled).toBe(true)

    const result2 = mockErrorHandler(unauthorizedError)
    expect(result2.message).toBe('Authentication Required')
    expect(result2.handled).toBe(true)

    const result3 = mockErrorHandler(notFoundError)
    expect(result3.message).toBe('Not Found')
    expect(result3.handled).toBe(true)

    expect(mockErrorHandler).toHaveBeenCalledTimes(3)
  })

  it('should handle network errors', () => {
    const mockNetworkErrorHandler = vi.fn((error) => {
      if (error.message.includes('fetch')) {
        return { type: 'network', handled: true }
      }
      return { type: 'unknown', handled: false }
    })

    const networkError = new Error('fetch failed')
    const result = mockNetworkErrorHandler(networkError)

    expect(result.type).toBe('network')
    expect(result.handled).toBe(true)
    expect(mockNetworkErrorHandler).toHaveBeenCalledWith(networkError)
  })

  it('should provide error context', () => {
    const mockContextProvider = vi.fn(() => ({
      isOnline: true,
      retryCount: 0,
      timestamp: new Date().toISOString()
    }))

    const context = mockContextProvider()
    
    expect(context.isOnline).toBe(true)
    expect(context.retryCount).toBe(0)
    expect(context.timestamp).toBeDefined()
    expect(mockContextProvider).toHaveBeenCalled()
  })

  it('should handle error recovery', () => {
    const mockRecovery = {
      attempts: 0,
      maxAttempts: 3,
      retry: vi.fn(function(this: any) {
        this.attempts++
        return this.attempts <= this.maxAttempts
      }),
      reset: vi.fn(function(this: any) {
        this.attempts = 0
      })
    }

    // Test retry logic
    expect(mockRecovery.retry()).toBe(true) // attempt 1
    expect(mockRecovery.retry()).toBe(true) // attempt 2
    expect(mockRecovery.retry()).toBe(true) // attempt 3
    expect(mockRecovery.retry()).toBe(false) // attempt 4, should fail

    expect(mockRecovery.attempts).toBe(4)

    // Test reset
    mockRecovery.reset()
    expect(mockRecovery.attempts).toBe(0)
  })
})